Workbook

Sheet PLAN DE CUENTAS
A1: CONTABILIDAD COMPUTARIZADA - ING. CRISTHIAN SAIQUITA
B2: PLAN DE CUENTAS
A4: CUENTA | B4: DESCRIPCION | C4: TIPO | D4: 1D | E4: 2D
A5: 1 | B5: ACTIVO | C5: 1 | D5: 1 | E5: 10
A6: 1.1 | B6: ACTIVO CORRIENTE | C6: 1 | D6: 1 | E6: 10
A7: 1.1.1 | B7: ACTIVO DISPONIBLE | C7: 1 | D7: 1 | E7: 10
A8: 1.1.1.01 | B8: CAJA MONEDA NACIONAL | C8: 1 | D8: 1 | E8: 10
A9: 1.1.1.02 | B9: FONDO FIJO DE CAJA CHICA | C9: 1 | D9: 1 | E9: 10
A10: 1.1.1.03 | B10: CAJA MONEDA EXTRANJERA | C10: 1 | D10: 1 | E10: 10
A11: 1.1.1.04 | B11: BANCO MONEDA NACIONAL | C11: 1 | D11: 1 | E11: 10
A12: 1.1.1.05 | B12: BANCO MONEDA EXTRANJERA | C12: 1 | D12: 1 | E12: 10
A13: 1.1.1.06 | B13: DEPOSITOS DE CAJA DE AHORRO | C13: 1 | D13: 1 | E13: 10
A14: 1.1.1.07 | B14: DEPOSITOS A PLAZO FIJO | C14: 1 | D14: 1 | E14: 10
A15: 1.1.2 | B15: ACTIVO EXIGIBLE | C15: 1 | D15: 1 | E15: 10
A16: 1.1.2.01 | B16: CUENTAS POR COBRAR | C16: 1 | D16: 1 | E16: 10
A17: 1.1.2.02 | B17: DOCUENTOS POR COBRAR | C17: 1 | D17: 1 | E17: 10
A18: 1.1.2.03 | B18: ANTICIPOS SOBRE SUELDOS | C18: 1 | D18: 1 | E18: 10
... A31: 1.1.3.05 | B31: MERCADERIAS EN MOSTRADOR | C31: 1 | D31: 1 | E31: 10
A32: 1.2 | B32: ACTIVO NO CORRIENTE | C32: 1 | D32: 1 | E32: 10
A33: 1.2.1 | B33: BIENES DE USO | C33: 1 | D33: 1 | E33: 10
A34: 1.2.1.01 | B34: TERRENOS | C34: 1 | D34: 1 | E34: 10
A35: 1.2.1.02 | B35: EDIFICIOS | C35: 1 | D35: 1 | E35: 10
A36: 1.2.1.03 | B36: MUEBLES Y ENSERES | C36: 1 | D36: 1 | E36: 10
A37: 1.2.1.04 | B37: VEHICULOS | C37: 1 | D37: 1 | E37: 10
A38: 1.2.1.05 | B38: EQUIPO DE COMPUTACION | C38: 1 | D38: 1 | E38: 10
A39: 1.2.1.06 | B39: EQUIPO DE LIMPIEZA | C39: 1 | D39: 1 | E39: 10
A40: 1.2.2 | B40: INVERSIONES | C40: 1 | D40: 1 | E40: 10
A41: 1.2.3 | B41: OTROS ACTIVOS | C41: 1 | D41: 1 | E41: 10
A42: 1.2.3.01 | B42: ACTIVOS DIFERIDOS | C42: 1 | D42: 1 | E42: 10
A43: 1.2.3.01.01 | B43: INVENTARIO MATERIAL DE ESCRITORIO | C43: 1 | D43: 1 | E43: 10
A44: 1.2.3.01.02 | B44: SEGUROS PAGADOS POR ADELANTADO | C44: 1 | D44: 1 | E44: 10
... A50: 1.2.3.02.01 | B50: EQUIPO DE COMPUTACION | C50: 1 | D50: 1 | E50: 10
A51: 2 | B51: PASIVO | C51: 2 | D51: 2 | E51: 20
A52: 2.1 | B52: PASIVO CORRIENTE | C52: 2 | D52: 2 | E52: 20
A53: 2.1.1 | B53: CUENTAS POR PAGAR M/N | C53: 2 | D53: 2 | E53: 20
A54: 2.1.2 | B54: CUENTAS POR PAGAR M/E | C54: 2 | D54: 2 | E54: 20
A55: 2.1.3 | B55: DOCUMENTOS POR PAGAR M/N | C55: 2 | D55: 2 | E55: 20
A56: 2.1.4 | B56: DOCUMENTOS POR PAGAR M/E | C56: 2 | D56: 2 | E56: 20
A57: 2.1.5 | B57: OBLIGACIONES CON EL PERSONAL | C57: 2 | D57: 2 | E57: 20
A58: 2.1.5.01 | B58: SUELDOS Y SALARIOS POR PAGAR | C58: 2 | D58: 2 | E58: 20
...

Sheet DIARIO
C2: LIBRO DIARIO | G2: DIFERENCIAS | H2: =+G3-H3 -> 0
F3: TOTALES | G3: =SUM(tdiario[DEBE]) -> 1701215.4 | H3: =SUM(tdiario[HABER]) -> 1701215.4
A5: NRO | B5: FECHA | C5: GLOSA | D5: OBS | E5: CUENTA | F5: DETALLE | G5: DEBE | H5: HABER
A6: 1 | B6: 45292 | C6: ASIENTO DE APERTURA | E6: 1.1.1.01 | F6: =IF(E6="","",VLOOKUP(tdiario[[#This Row],[CUENTA]],tcuentas[],2,FALSE)) -> CAJA MONEDA NACIONAL | G6: 140000
E7: 1.1.2.01 | F7: =IF(E7="","",VLOOKUP(tdiario[[#This Row],[CUENTA]],tcuentas[],2,FALSE)) -> CUENTAS POR COBRAR | G7: 13000
E8: 1.1.3.01 | F8: =IF(E8="","",VLOOKUP(tdiario[[#This Row],[CUENTA]],tcuentas[],2,FALSE)) -> INVENTARIO INICIAL | G8: 89000
E9: 1.2.1.01 | F9: =IF(E9="","",VLOOKUP(tdiario[[#This Row],[CUENTA]],tcuentas[],2,FALSE)) -> TERRENOS | G9: 25000
E10: 1.2.1.02 | F10: =IF(E10="","",VLOOKUP(tdiario[[#This Row],[CUENTA]],tcuentas[],2,FALSE)) -> EDIFICIOS | G10: 99000
E11: 1.2.1.04 | F11: =IF(E11="","",VLOOKUP(tdiario[[#This Row],[CUENTA]],tcuentas[],2,FALSE)) -> VEHICULOS | G11: 65000
E12: 1.2.1.03 | F12: =IF(E12="","",VLOOKUP(tdiario[[#This Row],[CUENTA]],tcuentas[],2,FALSE)) -> MUEBLES Y ENSERES | G12: 23000
E13: 2.1.3 | F13: =IF(E13="","",VLOOKUP(tdiario[[#This Row],[CUENTA]],tcuentas[],2,FALSE)) -> DOCUMENTOS POR PAGAR M/N | H13: 120000
E14: 3.1 | F14: =IF(E14="","",VLOOKUP(tdiario[[#This Row],[CUENTA]],tcuentas[],2,FALSE)) -> CAPITAL SOCIAL | H14: 334000
F15: =IF(E15="","",VLOOKUP(tdiario[[#This Row],[CUENTA]],tcuentas[],2,FALSE))
A16: 2 | B16: 45293 | C16: COMPRA DE MERCADERIA | E16: 1.1.3.02 | F16: =IF(E16="","",VLOOKUP(tdiario[[#This Row],[CUENTA]],tcuentas[],2,FALSE)) -> COMPRAS | G16: =H18-G17 -> 107010
E17: 1.1.2.06 | F17: =IF(E17="","",VLOOKUP(tdiario[[#This Row],[CUENTA]],tcuentas[],2,FALSE)) -> CREDITO FISCAL | G17: =H18*0.13 -> 15990
E18: 1.1.1.01 | F18: =IF(E18="","",VLOOKUP(tdiario[[#This Row],[CUENTA]],tcuentas[],2,FALSE)) -> CAJA MONEDA NACIONAL | H18: 123000
F19: =IF(E19="","",VLOOKUP(tdiario[[#This Row],[CUENTA]],tcuentas[],2,FALSE))
A20: 3 | B20: 45293 | C20: COMPRA DE MATERIAL DE LIMPIEZA | E20: 6.4.1.01 | F20: =IF(E20="","",VLOOKUP(tdiario[[#This Row],[CUENTA]],tcuentas[],2,FALSE)) -> ASEO Y LIMPIEZA | G20: =H22-G21 -> 1044
E21: 1.1.2.06 | F21: =IF(E21="","",VLOOKUP(tdiario[[#This Row],[CUENTA]],tcuentas[],2,FALSE)) -> CREDITO FISCAL | G21: =H22*0.13 -> 156
E22: 1.1.1.01 | F22: =IF(E22="","",VLOOKUP(tdiario[[#This Row],[CUENTA]],tcuentas[],2,FALSE)) -> CAJA MONEDA NACIONAL | H22: 1200
F23: =IF(E23="","",VLOOKUP(tdiario[[#This Row],[CUENTA]],tcuentas[],2,FALSE))
A24: 4 | B24: 45294 | C24: VENTA AL CONTADO | E24: 1.1.1.01 | F24: =IF(E24="","",VLOOKUP(tdiario[[#This Row],[CUENTA]],tcuentas[],2,FALSE)) -> CAJA MONEDA NACIONAL | G24: 160000
E25: 6.4.2.01 | F25: =IF(E25="","",VLOOKUP(tdiario[[#This Row],[CUENTA]],tcuentas[],2,FALSE)) -> GASTO IT | G25: =G24*0.03 -> 4800
E26: 5.1.1.01 | F26: =IF(E26="","",VLOOKUP(tdiario[[#This Row],[CUENTA]],tcuentas[],2,FALSE)) -> VENTAS | H26: =G24-H27 -> 139200
E27: 2.1.8 | F27: =IF(E27="","",VLOOKUP(tdiario[[#This Row],[CUENTA]],tcuentas[],2,FALSE)) -> DEBITO FISCAL | H27: =G24*0.13 -> 20800
E28: 2.1.7.06 | F28: =IF(E28="","",VLOOKUP(tdiario[[#This Row],[CUENTA]],tcuentas[],2,FALSE)) -> IT ACUMULADO POR PAGAR | H28: 4800
F29: =IF(E29="","",VLOOKUP(tdiario[[#This Row],[CUENTA]],tcuentas[],2,FALSE))
A30: 5 | B30: 45295 | C30: VENTA DE MERCADERIAS A CREDITO | E30: 1.1.2.01 | F30: =IF(E30="","",VLOOKUP(tdiario[[#This Row],[CUENTA]],tcuentas[],2,FALSE)) -> CUENTAS POR COBRAR | G30: 150000
E31: 6.4.2.01 | F31: =IF(E31="","",VLOOKUP(tdiario[[#This Row],[CUENTA]],tcuentas[],2,FALSE)) -> GASTO IT | G31: =G30*0.03 -> 4500
E32: 5.1.1.01 | F32: =IF(E32="","",VLOOKUP(tdiario[[#This Row],[CUENTA]],tcuentas[],2,FALSE)) -> VENTAS | H32: =G30-H33 -> 130500
E33: 2.1.8 | F33: =IF(E33="","",VLOOKUP(tdiario[[#This Row],[CUENTA]],tcuentas[],2,FALSE)) -> DEBITO FISCAL | H33: =G30*0.13 -> 19500
E34: 2.1.7.06 | F34: =IF(E34="","",VLOOKUP(tdiario[[#This Row],[CUENTA]],tcuentas[],2,FALSE)) -> IT ACUMULADO POR PAGAR | H34: 4500
F35: =IF(E35="","",VLOOKUP(tdiario[[#This Row],[CUENTA]],tcuentas[],2,FALSE))
A36: 6 | B36: 45296 | C36: DEVOL. SOBRE COMPRA | E36: 1.1.1.01 | F36: =IF(E36="","",VLOOKUP(tdiario[[#This Row],[CUENTA]],tcuentas[],2,FALSE)) -> CAJA MONEDA NACIONAL | G36: 12000
E37: 5.1.2.02 | F37: =IF(E37="","",VLOOKUP(tdiario[[#This Row],[CUENTA]],tcuentas[],2,FALSE)) -> DEVOLUCION Y BONIFICACION SOBRE COMPRAS | H37: =G36-H38 -> 10440
E38: 2.1.8 | F38: =IF(E38="","",VLOOKUP(tdiario[[#This Row],[CUENTA]],tcuentas[],2,FALSE)) -> DEBITO FISCAL | H38: =G36*0.13 -> 1560
F39: =IF(E39="","",VLOOKUP(tdiario[[#This Row],[CUENTA]],tcuentas[],2,FALSE))
A40: 7 | B40: 45297 | C40: VENTA DE MERCADERIAS AL CONTADO | E40: 1.1.1.01 | F40: =IF(E40="","",VLOOKUP(tdiario[[#This Row],[CUENTA]],tcuentas[],2,FALSE)) -> CAJA MONEDA NACIONAL | G40: 240000
E41: 6.4.2.01 | F41: =IF(E41="","",VLOOKUP(tdiario[[#This Row],[CUENTA]],tcuentas[],2,FALSE)) -> GASTO IT | G41: =G40*0.03 -> 7200
E42: 5.1.1.01 | F42: =IF(E42="","",VLOOKUP(tdiario[[#This Row],[CUENTA]],tcuentas[],2,FALSE)) -> VENTAS | H42: =G40-H43 -> 208800
...

Sheet HOJA DE TRABAJO
B1: BALANCE DE COMPROBACION
E3: SUMAS | G3: SALDOS | I3: BALANCE GENERAL | K3: ER NATURALEZA | M3: ESTADO DE RESULTADOS
A4: CUENTA | B4: DETALLE | C4: X | D4: Y | E4: DEBE | F4: HABER | G4: DEUDOR | H4: ACREEDOR | I4: ACTIVO | J4: PASIVO | K4: PERDIDA | L4: GANACIA | M4: PERDIDA2 | N4: GANACIA3
A5: =+'PLAN DE CUENTAS'!A5 -> 1 | B5: =+'PLAN DE CUENTAS'!B5 -> ACTIVO | C5: =+'PLAN DE CUENTAS'!C5 -> 1 | D5: =IF(tbal[[#This Row],[DEBE]]+tbal[[#This Row],[HABER]]=0,"","X") | E5: =SUMIF(tdiario[CUENTA],tbal[[#This Row],[CUENTA]],tdiario[DEBE]) -> 0 | F5: =SUMIF(tdiario[CUENTA],tbal[[#This Row],[CUENTA]],tdiario[HABER]) -> 0 | G5: =IF(tbal[[#This Row],[DEBE]]-tbal[[#This Row],[HABER]]>0,tbal[[#This Row],[DEBE]]-tbal[[#This Row],[HABER]],0) -> 0 | H5: =IF(tbal[[#This Row],[HABER]]-tbal[[#This Row],[DEBE]]>0,tbal[[#This Row],[HABER]]-tbal[[#This Row],[DEBE]],0) -> 0 | I5: =IF((OR(tbal[[#This Row],[X]]=1,tbal[[#This Row],[X]]=2)),tbal[[#This Row],[DEUDOR]],0) -> 0 | J5: =IF((OR(tbal[[#This Row],[X]]=2,tbal[[#This Row],[X]]=3)),tbal[[#This Row],[ACREEDOR]],0) -> 0 | K5: =IF((OR(tbal[[#This Row],[X]]=3,tbal[[#This Row],[X]]=5)),tbal[[#This Row],[DEUDOR]],0) -> 0 | L5: =IF((OR(tbal[[#This Row],[X]]=3,tbal[[#This Row],[X]]=4)),tbal[[#This Row],[ACREEDOR]],0) -> 0 | M5: =IF((OR(tbal[[#This Row],[X]]=0,tbal[[#This Row],[X]]=6)),tbal[[#This Row],[DEUDOR]],0) -> 0 | N5: =IF((OR(tbal[[#This Row],[X]]=0,tbal[[#This Row],[X]]=5)),tbal[[#This Row],[ACREEDOR]],0) -> 0
A6: =+'PLAN DE CUENTAS'!A6 -> 1.1 | B6: =+'PLAN DE CUENTAS'!B6 -> ACTIVO CORRIENTE | C6: =+'PLAN DE CUENTAS'!C6 -> 1 | D6: =IF(tbal[[#This Row],[DEBE]]+tbal[[#This Row],[HABER]]=0,"","X") | E6: =SUMIF(tdiario[CUENTA],tbal[[#This Row],[CUENTA]],tdiario[DEBE]) -> 0 | F6: =SUMIF(tdiario[CUENTA],tbal[[#This Row],[CUENTA]],tdiario[HABER]) -> 0 | G6: =IF(tbal[[#This Row],[DEBE]]-tbal[[#This Row],[HABER]]>0,tbal[[#This Row],[DEBE]]-tbal[[#This Row],[HABER]],0) -> 0 | H6: =IF(tbal[[#This Row],[HABER]]-tbal[[#This Row],[DEBE]]>0,tbal[[#This Row],[HABER]]-tbal[[#This Row],[DEBE]],0) -> 0 | I6: =IF((OR(tbal[[#This Row],[X]]=1,tbal[[#This Row],[X]]=2)),tbal[[#This Row],[DEUDOR]],0) -> 0 | J6: =IF((OR(tbal[[#This Row],[X]]=2,tbal[[#This Row],[X]]=3)),tbal[[#This Row],[ACREEDOR]],0) -> 0 | K6: =IF((OR(tbal[[#This Row],[X]]=3,tbal[[#This Row],[X]]=5)),tbal[[#This Row],[DEUDOR]],0) -> 0 | L6: =IF((OR(tbal[[#This Row],[X]]=3,tbal[[#This Row],[X]]=4)),tbal[[#This Row],[ACREEDOR]],0) -> 0 | M6: =IF((OR(tbal[[#This Row],[X]]=0,tbal[[#This Row],[X]]=6)),tbal[[#This Row],[DEUDOR]],0) -> 0 | N6: =IF((OR(tbal[[#This Row],[X]]=0,tbal[[#This Row],[X]]=5)),tbal[[#This Row],[ACREEDOR]],0) -> 0
A7: =+'PLAN DE CUENTAS'!A7 -> 1.1.1 | B7: =+'PLAN DE CUENTAS'!B7 -> ACTIVO DISPONIBLE | C7: =+'PLAN DE CUENTAS'!C7 -> 1 | D7: =IF(tbal[[#This Row],[DEBE]]+tbal[[#This Row],[HABER]]=0,"","X") | E7: =SUMIF(tdiario[CUENTA],tbal[[#This Row],[CUENTA]],tdiario[DEBE]) -> 0 | F7: =SUMIF(tdiario[CUENTA],tbal[[#This Row],[CUENTA]],tdiario[HABER]) -> 0 | G7: =IF(tbal[[#This Row],[DEBE]]-tbal[[#This Row],[HABER]]>0,tbal[[#This Row],[DEBE]]-tbal[[#This Row],[HABER]],0) -> 0 | H7: =IF(tbal[[#This Row],[HABER]]-tbal[[#This Row],[DEBE]]>0,tbal[[#This Row],[HABER]]-tbal[[#This Row],[DEBE]],0) -> 0 | I7: =IF((OR(tbal[[#This Row],[X]]=1,tbal[[#This Row],[X]]=2)),tbal[[#This Row],[DEUDOR]],0) -> 0 | J7: =IF((OR(tbal[[#This Row],[X]]=2,tbal[[#This Row],[X]]=3)),tbal[[#This Row],[ACREEDOR]],0) -> 0 | K7: =IF((OR(tbal[[#This Row],[X]]=3,tbal[[#This Row],[X]]=5)),tbal[[#This Row],[DEUDOR]],0) -> 0 | L7: =IF((OR(tbal[[#This Row],[X]]=3,tbal[[#This Row],[X]]=4)),tbal[[#This Row],[ACREEDOR]],0) -> 0 | M7: =IF((OR(tbal[[#This Row],[X]]=0,tbal[[#This Row],[X]]=6)),tbal[[#This Row],[DEUDOR]],0) -> 0 | N7: =IF((OR(tbal[[#This Row],[X]]=0,tbal[[#This Row],[X]]=5)),tbal[[#This Row],[ACREEDOR]],0) -> 0
A8: =+'PLAN DE CUENTAS'!A8 -> 1.1.1.01 | B8: =+'PLAN DE CUENTAS'!B8 -> CAJA MONEDA NACIONAL | C8: =+'PLAN DE CUENTAS'!C8 -> 1 | D8: =IF(tbal[[#This Row],[DEBE]]+tbal[[#This Row],[HABER]]=0,"","X") -> X | E8: =SUMIF(tdiario[CUENTA],tbal[[#This Row],[CUENTA]],tdiario[DEBE]) -> 719000 | F8: =SUMIF(tdiario[CUENTA],tbal[[#This Row],[CUENTA]],tdiario[HABER]) -> 398715.65 | G8: =IF(tbal[[#This Row],[DEBE]]-tbal[[#This Row],[HABER]]>0,tbal[[#This Row],[DEBE]]-tbal[[#This Row],[HABER]],0) -> 320284.35 | H8: =IF(tbal[[#This Row],[HABER]]-tbal[[#This Row],[DEBE]]>0,tbal[[#This Row],[HABER]]-tbal[[#This Row],[DEBE]],0) -> 0 | I8: =IF((OR(tbal[[#This Row],[X]]=1,tbal[[#This Row],[X]]=2)),tbal[[#This Row],[DEUDOR]],0) -> 320284.35 | J8: =IF((OR(tbal[[#This Row],[X]]=2,tbal[[#This Row],[X]]=3)),tbal[[#This Row],[ACREEDOR]],0) -> 0 | K8: =IF((OR(tbal[[#This Row],[X]]=3,tbal[[#This Row],[X]]=5)),tbal[[#This Row],[DEUDOR]],0) -> 0 | L8: =IF((OR(tbal[[#This Row],[X]]=3,tbal[[#This Row],[X]]=4)),tbal[[#This Row],[ACREEDOR]],0) -> 0 | M8: =IF((OR(tbal[[#This Row],[X]]=0,tbal[[#This Row],[X]]=6)),tbal[[#This Row],[DEUDOR]],0) -> 0 | N8: =IF((OR(tbal[[#This Row],[X]]=0,tbal[[#This Row],[X]]=5)),tbal[[#This Row],[ACREEDOR]],0) -> 0
A9: =+'PLAN DE CUENTAS'!A9 -> 1.1.1.02 | B9: =+'PLAN DE CUENTAS'!B9 -> FONDO FIJO DE CAJA CHICA | C9: =+'PLAN DE CUENTAS'!C9 -> 1 | D9: =IF(tbal[[#This Row],[DEBE]]+tbal[[#This Row],[HABER]]=0,"","X") | E9: =SUMIF(tdiario[CUENTA],tbal[[#This Row],[CUENTA]],tdiario[DEBE]) -> 0 | F9: =SUMIF(tdiario[CUENTA],tbal[[#This Row],[CUENTA]],tdiario[HABER]) -> 0 | G9: =IF(tbal[[#This Row],[DEBE]]-tbal[[#This Row],[HABER]]>0,tbal[[#This Row],[DEBE]]-tbal[[#This Row],[HABER]],0) -> 0 | H9: =IF(tbal[[#This Row],[HABER]]-tbal[[#This Row],[DEBE]]>0,tbal[[#This Row],[HABER]]-tbal[[#This Row],[DEBE]],0) -> 0 | I9: =IF((OR(tbal[[#This Row],[X]]=1,tbal[[#This Row],[X]]=2)),tbal[[#This Row],[DEUDOR]],0) -> 0 | J9: =IF((OR(tbal[[#This Row],[X]]=2,tbal[[#This Row],[X]]=3)),tbal[[#This Row],[ACREEDOR]],0) -> 0 | K9: =IF((OR(tbal[[#This Row],[X]]=3,tbal[[#This Row],[X]]=5)),tbal[[#This Row],[DEUDOR]],0) -> 0 | L9: =IF((OR(tbal[[#This Row],[X]]=3,tbal[[#This Row],[X]]=4)),tbal[[#This Row],[ACREEDOR]],0) -> 0 | M9: =IF((OR(tbal[[#This Row],[X]]=0,tbal[[#This Row],[X]]=6)),tbal[[#This Row],[DEUDOR]],0) -> 0 | N9: =IF((OR(tbal[[#This Row],[X]]=0,tbal[[#This Row],[X]]=5)),tbal[[#This Row],[ACREEDOR]],0) -> 0
A10: =+'PLAN DE CUENTAS'!A10 -> 1.1.1.03 | B10: =+'PLAN DE CUENTAS'!B10 -> CAJA MONEDA EXTRANJERA | C10: =+'PLAN DE CUENTAS'!C10 -> 1 | D10: =IF(tbal[[#This Row],[DEBE]]+tbal[[#This Row],[HABER]]=0,"","X") | E10: =SUMIF(tdiario[CUENTA],tbal[[#This Row],[CUENTA]],tdiario[DEBE]) -> 0 | F10: =SUMIF(tdiario[CUENTA],tbal[[#This Row],[CUENTA]],tdiario[HABER]) -> 0 | G10: =IF(tbal[[#This Row],[DEBE]]-tbal[[#This Row],[HABER]]>0,tbal[[#This Row],[DEBE]]-tbal[[#This Row],[HABER]],0) -> 0 | H10: =IF(tbal[[#This Row],[HABER]]-tbal[[#This Row],[DEBE]]>0,tbal[[#This Row],[HABER]]-tbal[[#This Row],[DEBE]],0) -> 0 | I10: =IF((OR(tbal[[#This Row],[X]]=1,tbal[[#This Row],[X]]=2)),tbal[[#This Row],[DEUDOR]],0) -> 0 | J10: =IF((OR(tbal[[#This Row],[X]]=2,tbal[[#This Row],[X]]=3)),tbal[[#This Row],[ACREEDOR]],0) -> 0 | K10: =IF((OR(tbal[[#This Row],[X]]=3,tbal[[#This Row],[X]]=5)),tbal[[#This Row],[DEUDOR]],0) -> 0 | L10: =IF((OR(tbal[[#This Row],[X]]=3,tbal[[#This Row],[X]]=4)),tbal[[#This Row],[ACREEDOR]],0) -> 0 | M10: =IF((OR(tbal[[#This Row],[X]]=0,tbal[[#This Row],[X]]=6)),tbal[[#This Row],[DEUDOR]],0) -> 0 | N10: =IF((OR(tbal[[#This Row],[X]]=0,tbal[[#This Row],[X]]=5)),tbal[[#This Row],[ACREEDOR]],0) -> 0
A11: =+'PLAN DE CUENTAS'!A11 -> 1.1.1.04 | B11: =+'PLAN DE CUENTAS'!B11 -> BANCO MONEDA NACIONAL | C11: =+'PLAN DE CUENTAS'!C11 -> 1 | D11: =IF(tbal[[#This Row],[DEBE]]+tbal[[#This Row],[HABER]]=0,"","X") | E11: =SUMIF(tdiario[CUENTA],tbal[[#This Row],[CUENTA]],tdiario[DEBE]) -> 0 | F11: =SUMIF(tdiario[CUENTA],tbal[[#This Row],[CUENTA]],tdiario[HABER]) -> 0 | G11: =IF(tbal[[#This Row],[DEBE]]-tbal[[#This Row],[HABER]]>0,tbal[[#This Row],[DEBE]]-tbal[[#This Row],[HABER]],0) -> 0 | H11: =IF(tbal[[#This Row],[HABER]]-tbal[[#This Row],[DEBE]]>0,tbal[[#This Row],[HABER]]-tbal[[#This Row],[DEBE]],0) -> 0 | I11: =IF((OR(tbal[[#This Row],[X]]=1,tbal[[#This Row],[X]]=2)),tbal[[#This Row],[DEUDOR]],0) -> 0 | J11: =IF((OR(tbal[[#This Row],[X]]=2,tbal[[#This Row],[X]]=3)),tbal[[#This Row],[ACREEDOR]],0) -> 0 | K11: =IF((OR(tbal[[#This Row],[X]]=3,tbal[[#This Row],[X]]=5)),tbal[[#This Row],[DEUDOR]],0) -> 0 | L11: =IF((OR(tbal[[#This Row],[X]]=3,tbal[[#This Row],[X]]=4)),tbal[[#This Row],[ACREEDOR]],0) -> 0 | M11: =IF((OR(tbal[[#This Row],[X]]=0,tbal[[#This Row],[X]]=6)),tbal[[#This Row],[DEUDOR]],0) -> 0 | N11: =IF((OR(tbal[[#This Row],[X]]=0,tbal[[#This Row],[X]]=5)),tbal[[#This Row],[ACREEDOR]],0) -> 0
A12: =+'PLAN DE CUENTAS'!A12 -> 1.1.1.05 | B12: =+'PLAN DE CUENTAS'!B12 -> BANCO MONEDA EXTRANJERA | C12: =+'PLAN DE CUENTAS'!C12 -> 1 | D12: =IF(tbal[[#This Row],[DEBE]]+tbal[[#This Row],[HABER]]=0,"","X") | E12: =SUMIF(tdiario[CUENTA],tbal[[#This Row],[CUENTA]],tdiario[DEBE]) -> 0 | F12: =SUMIF(tdiario[CUENTA],tbal[[#This Row],[CUENTA]],tdiario[HABER]) -> 0 | G12: =IF(tbal[[#This Row],[DEBE]]-tbal[[#This Row],[HABER]]>0,tbal[[#This Row],[DEBE]]-tbal[[#This Row],[HABER]],0) -> 0 | H12: =IF(tbal[[#This Row],[HABER]]-tbal[[#This Row],[DEBE]]>0,tbal[[#This Row],[HABER]]-tbal[[#This Row],[DEBE]],0) -> 0 | I12: =IF((OR(tbal[[#This Row],[X]]=1,tbal[[#This Row],[X]]=2)),tbal[[#This Row],[DEUDOR]],0) -> 0 | J12: =IF((OR(tbal[[#This Row],[X]]=2,tbal[[#This Row],[X]]=3)),tbal[[#This Row],[ACREEDOR]],0) -> 0 | K12: =IF((OR(tbal[[#This Row],[X]]=3,tbal[[#This Row],[X]]=5)),tbal[[#This Row],[DEUDOR]],0) -> 0 | L12: =IF((OR(tbal[[#This Row],[X]]=3,tbal[[#This Row],[X]]=4)),tbal[[#This Row],[ACREEDOR]],0) -> 0 | M12: =IF((OR(tbal[[#This Row],[X]]=0,tbal[[#This Row],[X]]=6)),tbal[[#This Row],[DEUDOR]],0) -> 0 | N12: =IF((OR(tbal[[#This Row],[X]]=0,tbal[[#This Row],[X]]=5)),tbal[[#This Row],[ACREEDOR]],0) -> 0
A13: =+'PLAN DE CUENTAS'!A13 -> 1.1.1.06 | B13: =+'PLAN DE CUENTAS'!B13 -> DEPOSITOS DE CAJA DE AHORRO | C13: =+'PLAN DE CUENTAS'!C13 -> 1 | D13: =IF(tbal[[#This Row],[DEBE]]+tbal[[#This Row],[HABER]]=0,"","X") | E13: =SUMIF(tdiario[CUENTA],tbal[[#This Row],[CUENTA]],tdiario[DEBE]) -> 0 | F13: =SUMIF(tdiario[CUENTA],tbal[[#This Row],[CUENTA]],tdiario[HABER]) -> 0 | G13: =IF(tbal[[#This Row],[DEBE]]-tbal[[#This Row],[HABER]]>0,tbal[[#This Row],[DEBE]]-tbal[[#This Row],[HABER]],0) -> 0 | H13: =IF(tbal[[#This Row],[HABER]]-tbal[[#This Row],[DEBE]]>0,tbal[[#This Row],[HABER]]-tbal[[#This Row],[DEBE]],0) -> 0 | I13: =IF((OR(tbal[[#This Row],[X]]=1,tbal[[#This Row],[X]]=2)),tbal[[#This Row],[DEUDOR]],0) -> 0 | J13: =IF((OR(tbal[[#This Row],[X]]=2,tbal[[#This Row],[X]]=3)),tbal[[#This Row],[ACREEDOR]],0) -> 0 | K13: =IF((OR(tbal[[#This Row],[X]]=3,tbal[[#This Row],[X]]=5)),tbal[[#This Row],[DEUDOR]],0) -> 0 | L13: =IF((OR(tbal[[#This Row],[X]]=3,tbal[[#This Row],[X]]=4)),tbal[[#This Row],[ACREEDOR]],0) -> 0 | M13: =IF((OR(tbal[[#This Row],[X]]=0,tbal[[#This Row],[X]]=6)),tbal[[#This Row],[DEUDOR]],0) -> 0 | N13: =IF((OR(tbal[[#This Row],[X]]=0,tbal[[#This Row],[X]]=5)),tbal[[#This Row],[ACREEDOR]],0) -> 0
A14: =+'PLAN DE CUENTAS'!A14 -> 1.1.1.07 | B14: =+'PLAN DE CUENTAS'!B14 -> DEPOSITOS A PLAZO FIJO | C14: =+'PLAN DE CUENTAS'!C14 -> 1 | D14: =IF(tbal[[#This Row],[DEBE]]+tbal[[#This Row],[HABER]]=0,"","X") | E14: =SUMIF(tdiario[CUENTA],tbal[[#This Row],[CUENTA]],tdiario[DEBE]) -> 0 | F14: =SUMIF(tdiario[CUENTA],tbal[[#This Row],[CUENTA]],tdiario[HABER]) -> 0 | G14: =IF(tbal[[#This Row],[DEBE]]-tbal[[#This Row],[HABER]]>0,tbal[[#This Row],[DEBE]]-tbal[[#This Row],[HABER]],0) -> 0 | H14: =IF(tbal[[#This Row],[HABER]]-tbal[[#This Row],[DEBE]]>0,tbal[[#This Row],[HABER]]-tbal[[#This Row],[DEBE]],0) -> 0 | I14: =IF((OR(tbal[[#This Row],[X]]=1,tbal[[#This Row],[X]]=2)),tbal[[#This Row],[DEUDOR]],0) -> 0 | J14: =IF((OR(tbal[[#This Row],[X]]=2,tbal[[#This Row],[X]]=3)),tbal[[#This Row],[ACREEDOR]],0) -> 0 | K14: =IF((OR(tbal[[#This Row],[X]]=3,tbal[[#This Row],[X]]=5)),tbal[[#This Row],[DEUDOR]],0) -> 0 | L14: =IF((OR(tbal[[#This Row],[X]]=3,tbal[[#This Row],[X]]=4)),tbal[[#This Row],[ACREEDOR]],0) -> 0 | M14: =IF((OR(tbal[[#This Row],[X]]=0,tbal[[#This Row],[X]]=6)),tbal[[#This Row],[DEUDOR]],0) -> 0 | N14: =IF((OR(tbal[[#This Row],[X]]=0,tbal[[#This Row],[X]]=5)),tbal[[#This Row],[ACREEDOR]],0) -> 0
A15: =+'PLAN DE CUENTAS'!A15 -> 1.1.2 | B15: =+'PLAN DE CUENTAS'!B15 -> ACTIVO EXIGIBLE | C15: =+'PLAN DE CUENTAS'!C15 -> 1 | D15: =IF(tbal[[#This Row],[DEBE]]+tbal[[#This Row],[HABER]]=0,"","X") | E15: =SUMIF(tdiario[CUENTA],tbal[[#This Row],[CUENTA]],tdiario[DEBE]) -> 0 | F15: =SUMIF(tdiario[CUENTA],tbal[[#This Row],[CUENTA]],tdiario[HABER]) -> 0 | G15: =IF(tbal[[#This Row],[DEBE]]-tbal[[#This Row],[HABER]]>0,tbal[[#This Row],[DEBE]]-tbal[[#This Row],[HABER]],0) -> 0 | H15: =IF(tbal[[#This Row],[HABER]]-tbal[[#This Row],[DEBE]]>0,tbal[[#This Row],[HABER]]-tbal[[#This Row],[DEBE]],0) -> 0 | I15: =IF((OR(tbal[[#This Row],[X]]=1,tbal[[#This Row],[X]]=2)),tbal[[#This Row],[DEUDOR]],0) -> 0 | J15: =IF((OR(tbal[[#This Row],[X]]=2,tbal[[#This Row],[X]]=3)),tbal[[#This Row],[ACREEDOR]],0) -> 0 | K15: =IF((OR(tbal[[#This Row],[X]]=3,tbal[[#This Row],[X]]=5)),tbal[[#This Row],[DEUDOR]],0) -> 0 | L15: =IF((OR(tbal[[#This Row],[X]]=3,tbal[[#This Row],[X]]=4)),tbal[[#This Row],[ACREEDOR]],0) -> 0 | M15: =IF((OR(tbal[[#This Row],[X]]=0,tbal[[#This Row],[X]]=6)),tbal[[#This Row],[DEUDOR]],0) -> 0 | N15: =IF((OR(tbal[[#This Row],[X]]=0,tbal[[#This Row],[X]]=5)),tbal[[#This Row],[ACREEDOR]],0) -> 0
A16: =+'PLAN DE CUENTAS'!A16 -> 1.1.2.01 | B16: =+'PLAN DE CUENTAS'!B16 -> CUENTAS POR COBRAR | C16: =+'PLAN DE CUENTAS'!C16 -> 1 | D16: =IF(tbal[[#This Row],[DEBE]]+tbal[[#This Row],[HABER]]=0,"","X") -> X | E16: =SUMIF(tdiario[CUENTA],tbal[[#This Row],[CUENTA]],tdiario[DEBE]) -> 163000 | F16: =SUMIF(tdiario[CUENTA],tbal[[#This Row],[CUENTA]],tdiario[HABER]) -> 75000 | G16: =IF(tbal[[#This Row],[DEBE]]-tbal[[#This Row],[HABER]]>0,tbal[[#This Row],[DEBE]]-tbal[[#This Row],[HABER]],0) -> 88000 | H16: =IF(tbal[[#This Row],[HABER]]-tbal[[#This Row],[DEBE]]>0,tbal[[#This Row],[HABER]]-tbal[[#This Row],[DEBE]],0) -> 0 | I16: =IF((OR(tbal[[#This Row],[X]]=1,tbal[[#This Row],[X]]=2)),tbal[[#This Row],[DEUDOR]],0) -> 88000 | J16: =IF((OR(tbal[[#This Row],[X]]=2,tbal[[#This Row],[X]]=3)),tbal[[#This Row],[ACREEDOR]],0) -> 0 | K16: =IF((OR(tbal[[#This Row],[X]]=3,tbal[[#This Row],[X]]=5)),tbal[[#This Row],[DEUDOR]],0) -> 0 | L16: =IF((OR(tbal[[#This Row],[X]]=3,tbal[[#This Row],[X]]=4)),tbal[[#This Row],[ACREEDOR]],0) -> 0 | M16: =IF((OR(tbal[[#This Row],[X]]=0,tbal[[#This Row],[X]]=6)),tbal[[#This Row],[DEUDOR]],0) -> 0 | N16: =IF((OR(tbal[[#This Row],[X]]=0,tbal[[#This Row],[X]]=5)),tbal[[#This Row],[ACREEDOR]],0) -> 0
... A2644: =+'PLAN DE CUENTAS'!A2644 -> 0 | B2644: =+'PLAN DE CUENTAS'!B2644 -> 0 | C2644: =+'PLAN DE CUENTAS'!C2644 -> 0 | D2644: =IF(tbal[[#This Row],[DEBE]]+tbal[[#This Row],[HABER]]=0,"","X") | E2644: =SUMIF(tdiario[CUENTA],tbal[[#This Row],[CUENTA]],tdiario[DEBE]) -> 0 | F2644: =SUMIF(tdiario[CUENTA],tbal[[#This Row],[CUENTA]],tdiario[HABER]) -> 0 | G2644: =IF(tbal[[#This Row],[DEBE]]-tbal[[#This Row],[HABER]]>0,tbal[[#This Row],[DEBE]]-tbal[[#This Row],[HABER]],0) -> 0 | H2644: =IF(tbal[[#This Row],[HABER]]-tbal[[#This Row],[DEBE]]>0,tbal[[#This Row],[HABER]]-tbal[[#This Row],[DEBE]],0) -> 0 | I2644: =IF((OR(tbal[[#This Row],[X]]=1,tbal[[#This Row],[X]]=2)),tbal[[#This Row],[DEUDOR]],0) -> 0 | J2644: =IF((OR(tbal[[#This Row],[X]]=2,tbal[[#This Row],[X]]=3)),tbal[[#This Row],[ACREEDOR]],0) -> 0 | K2644: =IF((OR(tbal[[#This Row],[X]]=3,tbal[[#This Row],[X]]=5)),tbal[[#This Row],[DEUDOR]],0) -> 0 | L2644: =IF((OR(tbal[[#This Row],[X]]=3,tbal[[#This Row],[X]]=4)),tbal[[#This Row],[ACREEDOR]],0) -> 0 | M2644: =IF((OR(tbal[[#This Row],[X]]=0,tbal[[#This Row],[X]]=6)),tbal[[#This Row],[DEUDOR]],0) -> 0 | N2644: =IF((OR(tbal[[#This Row],[X]]=0,tbal[[#This Row],[X]]=5)),tbal[[#This Row],[ACREEDOR]],0) -> 0
B2645: TOTALES | E2645: =SUBTOTAL(109,tbal[DEBE]) -> 1701215.4 | F2645: =SUBTOTAL(109,tbal[HABER]) -> 1701215.4 | G2645: =SUBTOTAL(109,tbal[DEUDOR]) -> 1094864.6 | H2645: =SUBTOTAL(109,tbal[ACREEDOR]) -> 1094864.6 | I2645: =SUM(tbal[ACTIVO]) -> 1010734.3 | J2645: =SUM(tbal[PASIVO]) -> 521900 | K2645: =SUBTOTAL(109,tbal[PERDIDA]) -> 0 | L2645: =SUBTOTAL(109,tbal[GANACIA]) -> 334000 | M2645: =SUBTOTAL(109,tbal[PERDIDA2]) -> 84130.25 | N2645: =SUBTOTAL(109,tbal[GANACIA3]) -> 572964.6
A2646: UTLIDAD O PÉRDIDA DE LA GESTION | J2646: =M2646 -> 488834.35 | M2646: =tbal[[#Totals],[GANACIA3]]-tbal[[#Totals],[PERDIDA2]] -> 488834.35
A2647: TOTALES | I2647: =tbal[[#Totals],[ACTIVO]] -> 1010734.3 | J2647: =tbal[[#Totals],[PASIVO]]+J2646 -> 1010734.3 | M2647: =tbal[[#Totals],[PERDIDA2]]+M2646 -> 572964.6 | N2647: =tbal[[#Totals],[GANACIA3]] -> 572964.6

Sheet BALANCE GENERAL
C2: BALANCE GENERAL
C3: EMPRESA VIDA SRL
C4: EXPRESADO EN BS.
B6: ACTIVO
B7: =+'PLAN DE CUENTAS'!B6 -> ACTIVO CORRIENTE | F7: =E8+E12+E15 -> 777424.35
B8: =+'PLAN DE CUENTAS'!B7 -> ACTIVO DISPONIBLE | E8: 320284.35
B9: =+'PLAN DE CUENTAS'!B8 -> CAJA MONEDA NACIONAL | D9: 320284.35
B12: ACTIVO EXIGIBLE | E12: 88000
B13: CUENTAS POR COBRAR | D13: 88000
B15: ACTIVO REALIZABLE | E15: 369140
B16: INVENTARIO INICIAL | D16: 89000
B17: COMPRAS | D17: 280140
B19: ACTIVO NO CORRIENTE | F19: 233310
B20: BIENES DE USO | E20: 233310
B21: TERRENOS | D21: 35000
B22: EDIFICIOS | D22: 99000
B23: MUEBLES Y ENSERES | D23: 23000
B24: VEHICULOS | D24: 65000
B25: EQUIPO DE COMPUTACION | D25: 11310
B27: TOTAL ACTIVO | G27: =F19+F7 -> 1010734.3
B29: PASIVO Y CAPITAL | G29: =F30+F36 -> 1010734.3
B30: PASIVO | F30: =SUM(E31:E33) -> 187900
B31: PASIVO CORRIENTE | E31: =SUM(D32:D34) -> 187900
B32: CUENTAS POR PAGAR M/N | D32: 49000
B33: DOCUMENTOS POR PAGAR M/N | D33: 120000
B34: IT ACUMULADO POR PAGAR | D34: 18900
B36: PATRIMONIO O CAPITAL CONTABLE | F36: =D37+D38 -> 822834.35
B37: CAPITAL SOCIAL | D37: 334000
B38: UTILIDAD DE LA GESTION | D38: 488834.35
B40: PASIVO Y CAPITAL | G40: =G29 -> 1010734.3

Sheet ESTADO DE RESULTADOS
B2: ESTADO DE RESULTADOS
B3: EMPRESA COMERCIAL VIDA SRL
B4: EXPRESADO EN BS.
F6: =SUM(E7:E9) -> 572964.6
B7: VENTAS | E7: 548100
A9: más | B9: OTROS INRESOS | E9: 24864.6
B10: DESCUENTOS SOBRE COMPRAS | D10: 1374.6
B11: DEVOLUCION Y BONIFICACION SOBRE COMPRAS | D11: 23490
B13: UTILIDAD BRUTA EN VENTAS | E13: 572964.6
F14: =E15+E21 -> 84130.25
A15: menos | B15: GASTOS OPERATIVOS | E15: =D16+D17+D18+D19 -> 71080.25
B16: ASEO Y LIMPIEZA | D16: 1044
B17: COMBUSTIBLES Y LUBRICANTES | D17: 1136.25
B18: GASTO IT | D18: 18900
B19: SUELDOS Y SALARIOS | D19: 50000
A21: menos | B21: OTROS EGRESOS | E21: =D22+D23 -> 13050
B22: DEVOLUCION Y BONIFICACION SOBRE VENTAS | D22: 10440
B23: DESCUENTOS SOBRE VENTAS | D23: 2610
B25: UTILIDAD DE LA GESTION | F25: 488834.35
B26: IUE (25%) | F26: 122208.59
B27: UTILIDAD NETA | F27: 366625.76
